Workbook

Sheet Booked Slots
A1: Timestamp | B1: Student Name | C1: Student Email | D1: Mobile Number | E1: Upload your resume | F1: Upload your progress card. Step 1: Go to Student Dashboard Step 2: Click on the menu on your left side-bar and go to "Documents for Download" section. Step 3: Search for "2026 Jan Progress Card" and download it. Step 4: Convert your resume into a single PDF, upload the PDF to your Google Drive, change the sharing settings to ‘Anyone with the link can view,’ and paste the link below. | G1: Slots (Timing in IST) – Data Science | H1: Slots (Timing in IST) – Programming

Sheet Sheet17
A1: Email | B1: Full Name (as per IIC Portal) | C1: Contact Num
A2: 23f1002434@ds.study.iitm.ac.in | B2: Deviprasad Nirjogi | C2: 7093383617
A3: 21f2000120@ds.study.iitm.ac.in | B3: R Hariharan | C3: 9841107493
A4: 22f3000694@ds.study.iitm.ac.in | B4: Achal Deep | C4: 8882475437
A5: 24ds2000089@ds.study.iitm.ac.in | B5: SHWETA VYAS | C5: 9166972279
A6: 24f2000612@ds.study.iitm.ac.in | B6: Udghosh Rao | C6: 9636039611
A7: 23f3001646@ds.study.iitm.ac.in | B7: Madhan Karthikeyan | C7: 9361951624
A8: 23f1002879@ds.study.iitm.ac.in | B8: Aayush Krishna | C8: 9263535027
A9: 23f2005014@ds.study.iitm.ac.in | B9: Soubhagya Nayak | C9: 9556794935
A10: 22f3000528@ds.study.iitm.ac.in | B10: kondaveeti muralidhar | C10: 8885312229
A11: 24f1000656@ds.study.iitm.ac.in | B11: Mokshada Chandrashekhar Nehete | C11: 9284969160
A12: 23f3004092@ds.study.iitm.ac.in | B12: Harliv Singh | C12: 7986041454
A13: 22f3002291@ds.study.iitm.ac.in | B13: Hardik D | C13: 6361433423
... A160: 23f2005282@ds.study.iitm.ac.in | B160: Shubham Singh | C160: 6291748061
A161: 21f3002151@ds.study.iitm.ac.in | B161: Saima Zainab Shroff | C161: NA
A162: 22f3002587@ds.study.iitm.ac.in | B162: Harshit Tiwari | C162: 7897049801
A163: 21f3001168@ds.study.iitm.ac.in | B163: Arnab Ghosh | C163: 9064659906
A164: 24f2000777@ds.study.iitm.ac.in | B164: Akshit Garg | C164: 9024050010
A165: 21f3002571@ds.study.iitm.ac.in | B165: Ghiridharan M G | C165: 9597293973
A166: 22f1000662@ds.study.iitm.ac.in | B166: Siddhanth Muragundi | C166: 7760092091
A167: 24f1002359@ds.study.iitm.ac.in | B167: Kaif Fazal | C167: 9504282350
A168: 21f2000502@ds.study.iitm.ac.in | B168: Subha Bhadra | C168: 7699816991
A169: 22f2000080@ds.study.iitm.ac.in | B169: Abhinandan Godara | C169: 8955022422
A170: 21f1003259@ds.study.iitm.ac.in | B170: Himanshu Singh | C170: 9140525531
A171: 25ds1000082@ds.study.iitm.ac.in | B171: G Sandeepp | C171: 8281183890
A172: 22f2000364@ds.study.iitm.ac.in | B172: Khushi Tiwari | C172: 7667717756
A173: 23f2004291@ds.study.iitm.ac.in | B173: Mili Parashar | C173: 8797217190
... A344: 24dp3000019@ds.study.iitm.ac.in | B344: Aditya Basavaraj Narthi | C344: 9538944471
A345: 22f3003206@ds.study.iitm.ac.in | B345: Parnikaa Basavanagudi Ramachandra | C345: NA
A346: 21f1001693@ds.study.iitm.ac.in | B346: Suhaas P | C346: 7396626025
A347: 21f3000828@ds.study.iitm.ac.in | B347: Bihari Azarudin Abidbhai | C347: 9638634737
A348: 22f3001115@ds.study.iitm.ac.in | B348: Aarush Agarwal | C348: 8700524258
A349: 23f2004247@ds.study.iitm.ac.in | B349: Pranesh Kumar | C349: 9798724149
A350: 22f2001256@ds.study.iitm.ac.in | B350: Hitesh | C350: 7988576592
A351: 22f3001352@ds.study.iitm.ac.in | B351: Rishav Kumar | C351: 9142347554
A352: 22f2000244@ds.study.iitm.ac.in | B352: Drishya Shrivastava | C352: 8319059935
A353: 21f2001124@ds.study.iitm.ac.in | B353: Samriddhi Sinha | C353: 8707484932
A354: 22f2001175@ds.study.iitm.ac.in | B354: Lakshika Sheoran | C354: 9717118189
A355: 21f3003099@ds.study.iitm.ac.in | B355: FASHMINA MOHAMED ABOOBUCKER | C355: 8148428241
A356: 22f3001778@ds.study.iitm.ac.in | B356: Deepak Singh | C356: 9999482864
...

Sheet FR6
A1: Timestamp | B1: Student Name | C1: Student Email | D1: Mobile Number | E1: Overall CGPA | F1: Upload your resume | G1: Upload your progress card. Step 1: Go to Student Dashboard Step 2: Click on the menu on your left side-bar and go to "Documents for Download" section. Step 3: Search for "2025 Sep Progress Card" and download it. Step 4: Convert your resume into a single PDF, upload the PDF to your Google Drive, change the sharing settings to ‘Anyone with the link can view,’ and paste the link below. | H1: Plan | I1: Which domain? | J1: Slots (Timing in IST) – Data Science | K1: Slots (Timing in IST) – Programming | L1: Email Address
A2: 46154.62 | B2: Thadeshwar Jay Jiteshbhai | C2: 23ds3000081@ds.study.iitm.ac.in | D2: 9727406861 | E2: 7.5 | F2: https://drive.google.com/drive/folders/1plpMz8e5gglH438PJktEqfaQJnctTDw1?usp=sharing | G2: NA | H2: Employment | I2: Data Science | J2: 14/05/2026 Thursday 08:30 AM - 08:45 AM (Data Science) | Lalit | L2: 23ds3000081@ds.study.iitm.ac.in
A3: 46154.621 | B3: Ritik Yadav | C3: 23f2004634@ds.study.iitm.ac.in | D3: 9350957047 | E3: 7.31 | F3: https://drive.google.com/file/d/1P6xYEABg8k22XoPIwllrRK3i_TLL1zp9/view?usp=sharing | G3: https://drive.google.com/file/d/19ttHHHHE-JCq1lQV9NVX1zERzjKihUfF/view?usp=drive_link | H3: Internship | I3: Data Science | J3: 15/05/2026 Friday 04:30 PM - 05:00 PM (Data Science) | Mayur | L3: 23f2004634@ds.study.iitm.ac.in
A4: 46160.802 | B4: Pinki | C4: 23f2003874@ds.study.iitm.ac.in | D4: 9813743480 | E4: 7.95 | F4: https://drive.google.com/file/d/104nryzwyTS7FFFtk2SRj3W6-gmzFSbvZ/view?usp=drivesdk | G4: https://drive.google.com/file/d/10Xx36gjUQpW9BReDRIhUKnQZXjNmSbH8/view?usp=drivesdk | H4: Internship | I4: Data Science | J4: 21/05/2026 Thursday 12:15 PM - 12:30 PM (Data Science) | Lalit | L4: 23f2003874@ds.study.iitm.ac.in
A5: 46160.808 | B5: KHUSHI TIWARI | C5: 22f2000364@ds.study.iitm.ac.in | D5: 7667717756 | E5: 6.44 | F5: https://drive.google.com/file/d/1YWHD3jAHOFa5Kaq-FloX-AIujtLq4u0f/view?usp=sharing | G5: https://drive.google.com/file/d/1f4FyNWMyVH4cBz_oZeu4rVoJz5XQzrNd/view?usp=sharing | H5: Internship | I5: Data Science | J5: 22/05/2026 Friday 11:45 AM - 12:00 PM (Data Science) | Lalit | L5: 22f2000364@ds.study.iitm.ac.in
A6: 46154.622 | B6: Tarika Subhash Hedaoo | C6: 22f3002758@ds.study.iitm.ac.in | D6: 9003928895 | E6: 9.49 | F6: https://drive.google.com/file/d/1NAazOZbu1df-SDPtu4dui42cOlqB33IJ/view?usp=drive_link | G6: https://drive.google.com/file/d/1kxHHAYjV-0l-9BYvueiHc1NBdYGYWdxE/view?usp=sharing | H6: Internship | I6: Data Science | J6: 15/05/2026 Friday 08:45 AM - 09:00 AM (Data Science) | Lalit | L6: 22f3002758@ds.study.iitm.ac.in
A7: 46160.798 | B7: Achal Deep | C7: 22f3000694@ds.study.iitm.ac.in | D7: 8882475437 | E7: 8.53 | F7: https://drive.google.com/file/d/1dnkJ-vM-XWS0jQYbzdgkCt5cmVFlGiI3/view?usp=drivesdk | G7: https://drive.google.com/file/d/1j7b48SLkwWMnmm6Lo2z1_Ny8u0_B8t-9/view?usp=drivesdk | H7: Internship | I7: Data Science | J7: 22/05/2026 Friday 11:15 AM - 11:30 AM (Data Science) | Lalit | L7: 22f3000694@ds.study.iitm.ac.in
A8: 46160.904 | B8: Sneha Dutta | C8: 21f1001697@ds.study.iitm.ac.in | D8: 8017767311 | E8: 7.1 | F8: https://drive.google.com/file/d/12FnWB0j_Ezsh66xPIf2lDDBsnIy2UIbD/view?usp=sharing | G8: https://drive.google.com/file/d/1PE8Ju7_dNpRVATTaeR9sjkKFt8ASdldy/view?usp=sharing | H8: Internship | I8: Data Science | J8: 20/05/2026 Wednesday 11:30 AM - 11:45 AM (Data Science) | Lalit | L8: 21f1001697@ds.study.iitm.ac.in
A9: 46160.868 | B9: Shreya Shambhavi | C9: 21f1001507@ds.study.iitm.ac.in | D9: 9631575721 | E9: 7.74 | F9: https://drive.google.com/file/d/1YKeu4fMigVOgPUkD8ABpTDiDHRCrC22r/view?usp=drivesdk | G9: https://drive.google.com/file/d/1gP4-zU_j3moB2WMJpavurLQSgKaqW8CW/view?usp=drivesdk | H9: Employment | I9: Data Science | J9: 20/05/2026 Wednesday 12:45 PM - 01:00 PM (Data Science) | Lalit | L9: 21f1001507@ds.study.iitm.ac.in
A10: 46160.815 | B10: BRAHMKSHATRIYA SHIVAM ATULBHAI | C10: 23ds3000034@ds.study.iitm.ac.in | D10: 7203954367 | E10: 6.31 | F10: https://drive.google.com/file/d/1bNjKxB2lJR57hnNxit6GrieFf6n2Hfod/view?usp=sharing | G10: https://drive.google.com/file/d/14BxzLGnxzbMj5nedQ9qOqY0xioaBmu_y/view?usp=sharing | H10: Internship | I10: Data Science | J10: 21/05/2026 Thursday 12:00 PM - 12:15 PM (Data Science) | Lalit | L10: 23ds3000034@ds.study.iitm.ac.in
A11: 46154.63 | B11: Akula Geetha Maheswari | C11: 21f3000254@ds.study.iitm.ac.in | D11: 7661838282 | E11: 8.4 | F11: https://drive.google.com/file/d/1gjHj2KHfSH9PHa6LZBzLc6AHpa32Askh/view?usp=sharing | G11: https://drive.google.com/file/d/1-aVk61y8QHF2cpQL-5dFxAFw7DR48WhC/view?usp=sharing | H11: Employment | I11: Data Science | J11: 15/05/2026 Friday 08:30 AM - 08:45 AM (Data Science) | Lalit | L11: 21f3000254@ds.study.iitm.ac.in
A12: 46160.812 | B12: Harsh Pratap Singh | C12: 22f3002166@ds.study.iitm.ac.in | D12: 8077448501 | E12: 7.6 | F12: https://drive.google.com/file/d/1I9nSTF_NIAoHtVsZk-_5ssn0HWg3fUIV/view?usp=sharing | G12: https://drive.google.com/file/d/147eP9Hs5KWGSAiFGHrzD94IiLC-CGknh/view?usp=sharing | H12: Internship | I12: Data Science | J12: 22/05/2026 Friday 11:30 AM - 11:45 AM (Data Science) | Lalit | L12: 22f3002166@ds.study.iitm.ac.in
A13: 46154.644 | B13: Drishya shrivastava | C13: 22f2000244@ds.study.iitm.ac.in | D13: 8319059935 | E13: 6.95 | F13: https://drive.google.com/drive/folders/15cf4vd8QrsJuNSo1S7XkCRJkQSN02Bk-?usp=sharing | G13: https://drive.google.com/file/d/1dr2ap37uMy9pAN48mAIO98noiuZAAbNP/view?usp=sharing | H13: Internship | I13: Data Science | J13: 15/05/2026 Friday 04:00 PM - 04:30 PM (Data Science) | Nikitakumari | L13: drishya.shrivastava11@gmail.com
... A33: 46160.797 | B33: Hiyaa Thaker | C33: 22f3002191@ds.study.iitm.ac.in | D33: 8319347881 | E33: 8.59 | F33: https://drive.google.com/file/d/1eyfd-nKG1JBhJAJ-viY-_jpEtss_brjJ/view?usp=drive_link | G33: https://drive.google.com/file/d/1O06XLBiYr9fZ3QiEzFplRBOBYvKZyuaS/view?usp=drive_link | H33: Internship | I33: Data Science | J33: 22/05/2026 Friday 11:00 AM - 11:15 AM (Data Science) | Lalit | L33: 22f3002191@ds.study.iitm.ac.in
A34: 46160.8 | B34: Rishav Kumar | C34: 23f1003150@ds.study.iitm.ac.in | D34: 9546667831 | E34: 7.03 | F34: https://drive.google.com/file/d/1q9sr5vpfPJMEbxg4uZ4au1Pmt8hYluRA/view?usp=drivesdk | G34: https://drive.google.com/file/d/1q8Qak1ATuHxIOt0XCo1RkZ3Toe2mzhUe/view?usp=drivesdk | H34: Internship | I34: Programming | K34: 20/05/2026 Wednesday 05:30 PM - 06:00 PM (Programming) | Shivani | L34: 23f1003150@ds.study.iitm.ac.in
A35: 46160.806 | B35: Sujit Laware | C35: 22f3002016@ds.study.iitm.ac.in | D35: 9970208412 | E35: 6.47 | F35: https://drive.google.com/file/d/1FlYkjhEchru5bQPMVpqCCksMrOwN8bdH/view?usp=sharing | G35: https://drive.google.com/file/d/1ie3HlSQtIKLp3bkyz5JUht4NEIbHvFBN/view?usp=sharing | H35: Internship | I35: Programming | K35: 21/05/2026 Thursday 05:30 PM - 06:00 PM (Programming) | Shivani | L35: 22f3002016@ds.study.iitm.ac.in
A36: 46160.807 | B36: Saksham gupta | C36: 22f3000721@ds.study.iitm.ac.in | D36: 8302045298 | E36: 6.26 | F36: https://drive.google.com/drive/folders/15zpwSWGoKbaSisg10MF7jsTZXp40nrmH | G36: https://drive.google.com/file/d/1d1QqJioNJJRRWyp-g6mxkmJrq-wxsraV/view?usp=drivesdk | H36: Internship | I36: Data Science | J36: 22/05/2026 Friday 12:15 PM - 12:30 PM (Data Science) | Lalit | L36: 22f3000721@ds.study.iitm.ac.in
A37: 46160.812 | B37: muralidhar k | C37: 22f3000528@ds.study.iitm.ac.in | D37: 8885312229 | E37: 7.64 | F37: https://drive.google.com/file/d/1xZr5oa2vTk-UJjA9yGj8le5m4cYwCzWg/view?usp=sharing | G37: https://drive.google.com/file/d/1FQdlztLwEPAvE6VlPvfaIZrD0iEUqtg5/view?usp=sharing | H37: Internship | I37: Data Science | J37: 22/05/2026 Friday 01:00 PM - 01:15 PM (Data Science) | Lalit | L37: 22f3000528@ds.study.iitm.ac.in
A38: 46160.813 | B38: Abhishek Dutta | C38: 22f3001838@ds.study.iitm.ac.in | D38: 7004553719 | E38: 8.44 | F38: https://drive.google.com/file/d/1L68Kes5MHHVp4uzDfXlNWSRdSDpZfD-4/view?usp=drivesdk | G38: https://drive.google.com/file/d/11ZcDbRJIlvc4KCmZePHAhYKSyIWR5kTS/view?usp=drivesdk | H38: Internship | I38: Data Science | J38: 21/05/2026 Thursday 12:45 PM - 01:00 PM (Data Science) | Lalit | L38: 22f3001838@ds.study.iitm.ac.in
A39: 46160.823 | B39: Bhargavi Jaiswal | C39: 23f3002094@ds.study.iitm.ac.in | D39: 7069055104 | E39: 8 | F39: https://drive.google.com/file/d/1q-fuKCYdKP47EYv4CwIwZQKJCM1ZJJ-A/view?usp=sharing | G39: https://drive.google.com/file/d/1J3BHa8zz8jC5BSubH2FQ1gzNhknREZsT/view?usp=sharing | H39: Internship | I39: Data Science | J39: 21/05/2026 Thursday 12:30 PM - 12:45 PM (Data Science) | Lalit | L39: 23f3002094@ds.study.iitm.ac.in
A40: 46160.828 | B40: Anurag Pandey | C40: 22f1000812@ds.study.iitm.ac.in | D40: 9359412921 | E40: 6.22 | F40: https://drive.google.com/file/d/14DlK4ajl14lN9ZQNLoJhsR21QoyOwsT-/view?usp=sharing | G40: https://drive.google.com/file/d/1hX2DT-LPlHjFzvvBhCNPD1o7_1Q4rHn5/view?usp=sharing | H40: Internship | I40: Data Science | J40: 21/05/2026 Thursday 11:00 AM - 11:15 AM (Data Science) | Lalit | L40: luvyansh2001@gmail.com
A41: 46160.833 | B41: Darshan Ganatra | C41: 22f2000931@ds.study.iitm.ac.in | D41: 9429563006 | E41: 9.01 | F41: https://drive.google.com/file/d/11irWen5Fj5M5cZt2FH6YrLokg2McoGGT/view?usp=drive_link | G41: https://drive.google.com/file/d/1XasjA669qQjsXL_I915LaOrYpQ0Ln4ui/view?usp=drivesdk | H41: Internship | I41: Data Science | J41: 21/05/2026 Thursday 11:30 AM - 11:45 AM (Data Science) | Lalit | L41: 22f2000931@ds.study.iitm.ac.in
A42: 46160.833 | B42: Sarwar karim akhand | C42: 21f1006953@ds.study.iitm.ac.in | D42: 8350097169 | E42: 7.51 | F42: https://docs.google.com/document/d/1D5OlM8JbeVHn2rFX956AhdaeyrkK5eNFk1IrtNA09no/edit?usp=sharing | G42: https://drive.google.com/file/d/1lO4qX-vqy6x-MtKC4syRSGzrao64BLPY/view?usp=sharing | H42: Internship | I42: Data Science | J42: 21/05/2026 Thursday 11:45 AM - 12:00 PM (Data Science) | Lalit | L42: aksarwar8@gmail.com
A43: 46160.839 | B43: Vidhatri H R | C43: 23f2000575@ds.study.iitm.ac.in | D43: 9449421763 | E43: 7.3 | F43: https://drive.google.com/file/d/1qoju7aS9GsB7oipcpx73KWLfJozgQE28/view?usp=drivesdk | G43: https://drive.google.com/file/d/1sIcg5_NPOIlpfFkcUMhBH5oR9Dd_0nCU/view?usp=drivesdk | H43: Internship | I43: Programming | K43: 21/05/2026 Thursday 05:00 PM - 05:30 PM (Programming) | Shivani | L43: 23f2000575@ds.study.iitm.ac.in
A44: 46160.839 | B44: Adhyan Mishra | C44: 23f2000260@ds.study.iitm.ac.in | D44: 8368322631 | E44: 7.35 | F44: https://drive.google.com/file/d/1BRFlndqHUXMD5ECEdQj-Vaz-wOBh04Gc/view?usp=sharing | G44: https://drive.google.com/file/d/13Ejj0sIciJ4V2FH9RjIkyq6nsitrgmJ0/view?usp=sharing | H44: Internship | I44: Programming | K44: 20/05/2026 Wednesday 05:30 PM - 06:00 PM (Programming) | Atul | L44: 23f2000260@ds.study.iitm.ac.in
A45: 46160.855 | B45: Swati Jain | C45: 21f3000759@ds.study.iitm.ac.in | D45: 8697001351 | E45: 8.34 | F45: https://drive.google.com/drive/folders/1a0jYoxINKTim4WrX6f6C9SisM7xmz-Vw?usp=sharing | G45: https://drive.google.com/file/d/1r-SADzmGOP2h2iO4neVkBlkEbUK3lk0B/view?usp=sharing | H45: Internship | I45: Programming | K45: 21/05/2026 Thursday 04:00 PM - 04:30 PM (Programming) | Satyanarayana | L45: 21f3000759@ds.study.iitm.ac.in
A46: 46160.863 | B46: Samyuktha Shriram | C46: 22f2001444@ds.study.iitm.ac.in | D46: 8073125787 | E46: 8.38 | F46: https://drive.google.com/file/d/1MMeXnkcMRC8gjZbNnAy6lDqrnZ3kwQEw/view?usp=sharing | G46: https://drive.google.com/file/d/1XTtZ72YsF8MZFshrXHPsgr36fGsGuVlC/view?usp=sharing | H46: Internship | I46: Data Science | J46: 20/05/2026 Wednesday 11:00 AM - 11:15 AM (Data Science) | Lalit | L46: 22f2001444@ds.study.iitm.ac.in
A47: 46160.891 | B47: B Sarveshraj | C47: 23f2000592@ds.study.iitm.ac.in | D47: 8870129519 | E47: 7.12 | F47: https://drive.google.com/file/d/1xRR_xqUbQ2SbqtsmJKPksufdIQMRFP6p/view?usp=sharing | G47: https://drive.google.com/file/d/1rw7xj5WLGl8GqftwZNKPzbzSnToZ2laD/view?usp=drive_link | H47: Internship | I47: Programming | K47: 20/05/2026 Wednesday 04:00 PM - 04:30 PM (Programming) | Shubhamy | L47: 23f2000592@ds.study.iitm.ac.in
A48: 46160.91 | B48: Soumyabrata Mahapatra | C48: 21f1003070@ds.study.iitm.ac.in | D48: 7003471206 | E48: 8.2 | F48: https://drive.google.com/file/d/1psor718YKY_FTemErGOEOk4fmUGzhX1f/view?usp=sharing | G48: https://drive.google.com/file/d/1rqigoWIAzfdzpGvg-NENFkNsg6dIAs9d/view?usp=sharing | H48: Internship | I48: Data Science | J48: 20/05/2026 Wednesday 12:00 PM - 12:15 PM (Data Science) | Lalit | L48: 21f1003070@ds.study.iitm.ac.in
A49: 46160.922 | B49: Tushar Jalan | C49: 23f2003751@ds.study.iitm.ac.in | D49: 8240558484 | E49: 8 | F49: https://drive.google.com/file/d/1Tij6rslpAjVLicDDggixGtswMWNJgImS/view?usp=sharing | G49: https://drive.google.com/file/d/1mAuz7PgPUfAoOV97zUbWvP6m-v1z3IVx/view?usp=sharing | H49: Internship | I49: Programming | K49: 20/05/2026 Wednesday 05:00 PM - 05:30 PM (Programming) | Atul | L49: 23f2003751@ds.study.iitm.ac.in
A50: 46160.934 | B50: Prateek Sharma | C50: 24dp1000047@ds.study.iitm.ac.in | D50: 8219407196 | E50: 6.71 | F50: https://drive.google.com/file/d/1a1k1lQRkAqXhXsP4XnEUIor8rs3zEcPS/view?usp=sharing | G50: https://drive.google.com/file/d/1GD9I9nOajHaoxMcQrN_BZrR2D9qB8GYv/view?usp=sharing | H50: Internship | I50: Programming | K50: 21/05/2026 Thursday 04:30 PM - 05:00 PM (Programming) | Adarsh | L50: 24dp1000047@ds.study.iitm.ac.in
A51: 46160.94 | B51: Daaris Ameen | C51: 21f1001365@ds.study.iitm.ac.in | D51: 9791187785 | E51: 8.13 | F51: https://drive.google.com/file/d/1zopi9XjsWXBJRc70wTgEPcMJ6dwLw6F9/view?usp=sharing | G51: https://drive.google.com/file/d/1b8kJhhwTNoJ1k3M_c35ATHX8pK--6ooM/view?usp=sharing | H51: Employment | I51: Programming | K51: 20/05/2026 Wednesday 07:30 PM - 08:00 PM (Programming) | Afnan | L51: 21f1001365@ds.study.iitm.ac.in
A52: 46160.953 | B52: Sidhant kumar | C52: 23f1001556@ds.study.iitm.ac.in | D52: 8540060180 | E52: 6.03 | F52: https://drive.google.com/file/d/1KvuAx4KseZ9dR661mqvTbcHiUiBjP-rU/view?usp=sharing | G52: https://drive.google.com/file/d/1mZVR3klWRe-JQZNlj5x1x9jszhkZ30_9/view?usp=sharing | H52: Internship | I52: Programming | K52: 21/05/2026 Thursday 04:00 PM - 04:30 PM (Programming) | Atul | L52: sidhantsksk@gmail.com
A53: 46161.474 | B53: Vivekanand kumawat | C53: 23f2004577@ds.study.iitm.ac.in | D53: 9828251124 | E53: 7.23 | F53: https://drive.google.com/file/d/1_dXDqRmolyJoobPNt0PIV8JAcIc1lhxY/view?usp=sharing | G53: https://drive.google.com/file/d/1Pnl_keG3ML4ltTH1U71ovZFPxzUPbw7m/view?usp=sharing | H53: Internship | I53: Programming | K53: 21/05/2026 Thursday 04:30 PM - 05:00 PM (Programming) | Shubhamy | L53: vivekanandkumawat261@gmail.com

Sheet FR5
A1: Timestamp | B1: Student Name | C1: Student Email | D1: Mobile Number | E1: Overall CGPA | F1: Upload your resume | G1: Upload your progress card. Step 1: Go to Student Dashboard Step 2: Click on the menu on your left side-bar and go to "Documents for Download" section. Step 3: Search for "2025 Sep Progress Card" and download it. Step 4: Convert your resume into a single PDF, upload the PDF to your Google Drive, change the sharing settings to ‘Anyone with the link can view,’ and paste the link below. | H1: Plan | I1: Which domain? | J1: Slots (Timing in IST) – Data Science | K1: Slots (Timing in IST) – Programming | L1: Email Address
A2: 46130.686 | B2: Harsh Pratap Singh | C2: 22f3002166@ds.study.iitm.ac.in | D2: 8077448501 | E2: 7.6 | F2: https://drive.google.com/file/d/1_XKfMwRib59rb-TqGttiOE1gHSNEdEVt/view?usp=sharing | G2: https://drive.google.com/file/d/1zvMBwHTHK-Bu_bsdGSOYCZ6h6BGas1U1/view?usp=sharing | H2: Internship | I2: Data Science | J2: 31/03/2026 Tuesday 05:00 PM - 05:30 PM (Data Science) | Karthik | L2: 22f3002166@ds.study.iitm.ac.in
A3: 46131.837 | B3: Rishav Kumar | C3: 22f3001352@ds.study.iitm.ac.in | D3: 9142347554 | E3: 7.4 | F3: https://drive.google.com/file/d/1LD_qcJGhcV_7lHjfyh2o0u-X7uwI08jZ/view?usp=drivesdk | G3: https://drive.google.com/file/d/1Mt2IX9ojnCtNiGz30yBc6NqBGaSGAwI5/view?usp=drivesdk | H3: Internship | I3: Data Science | J3: 23/04/2026 Thursday 04:00 PM - 04:30 PM (Data Science) | Nikitakumari | L3: 22f3001352@ds.study.iitm.ac.in
A4: 46131.841 | B4: Niraj Kumar | C4: 21f1006589@ds.study.iitm.ac.in | D4: 9570194524 | E4: 7.14 | F4: https://drive.google.com/file/d/1rZI7-SiZAOB7NUnsO9n68cEl-txaqh7W/view?usp=drivesdk | G4: https://drive.google.com/file/d/15mwRkXLr_nCW1QTHNTsoVpOHfm87Bm_E/view?usp=drivesdk | H4: Internship | I4: Data Science | J4: 28/04/2026 Tuesday 04:30 PM - 05:00 PM (Data Science) | Karthik | L4: 21f1006589@ds.study.iitm.ac.in
A5: 46131.844 | B5: Ritik Yadav | C5: 23f2004634@ds.study.iitm.ac.in | D5: 9350957047 | E5: 7.31 | F5: https://drive.google.com/file/d/1SEX7TP0yIDthFcTAbfEem16TvQWCOXvB/view?usp=drive_link | G5: https://drive.google.com/file/d/19ttHHHHE-JCq1lQV9NVX1zERzjKihUfF/view?usp=sharing | H5: Internship | I5: Data Science | J5: 20/04/2026 Monday 05:00 PM - 05:30 PM (Data Science) | Lalit | L5: 23f2004634@ds.study.iitm.ac.in
A6: 46131.845 | B6: Aryan Thakur | C6: 23f1000966@ds.study.iitm.ac.in | D6: 8287770250 | E6: 7.52 | F6: https://drive.google.com/file/d/1zA06ykxUNA1JtZ1u3nE5qljbkrn88AH3/view?usp=sharing | G6: https://drive.google.com/file/d/1aCN3RnxdiyZ6iTOKy05d8oSXAy6Vbn7J/view?usp=sharing | H6: Internship | I6: Data Science | J6: 28/04/2026 Tuesday 04:00 PM - 04:30 PM (Data Science) | Nikitakumari | L6: aryanthakur9953@gmail.com
A7: 46131.848 | B7: Aviral Choudhary | C7: 23f3004412@ds.study.iitm.ac.in | D7: 9877483716 | E7: 8.26 | F7: https://drive.google.com/file/d/11sDo5chObH8qerDgg5-NtoVKTNGRnPtY/view?usp=sharing | G7: https://drive.google.com/file/d/1k8faK3bMy1ZWvJjkUKFf1nU5qRIAMQsj/view?usp=sharing | H7: Internship | I7: Data Science | J7: 27/04/2026 Monday 04:30 PM - 05:00 PM (Data Science) | Karthik | L7: 23f3004412@ds.study.iitm.ac.in
A8: 46131.848 | B8: Hariom Kashyap | C8: 21f2000584@ds.study.iitm.ac.in | D8: 8544032450 | E8: 6.41 | F8: https://drive.google.com/drive/folders/1xZNIiTGuyv1Hszfso4rbI60U3Gfne1TF?usp=sharing | G8: https://drive.google.com/drive/folders/1HwInnQ0S1PiIApES6OAFeyHT46fw62fe?usp=sharing | H8: Internship | I8: Data Science | J8: 23/04/2026 Thursday 05:30 PM - 06:00 PM (Data Science) | Lalit | L8: kashyapcode@gmail.com
A9: 46131.854 | B9: Areeba Farooqui | C9: 22f1001053@ds.study.iitm.ac.in | D9: 9026479584 | E9: 8.47 | F9: https://drive.google.com/file/d/1UpPdqNxKPc_sr1wGrrA54V7ggYuBblY8/view?usp=drive_link | G9: https://drive.google.com/file/d/14bQmbEdmUXmm8Av1ERL5ZGJE_Yj1qS1T/view?usp=drive_link | H9: Employment | I9: Data Science | J9: 23/04/2026 Thursday 05:00 PM - 05:30 PM (Data Science) | Lalit | L9: 22f1001053@ds.study.iitm.ac.in
A10: 46131.854 | B10: Deepak Kumar | C10: 22f3000107@ds.study.iitm.ac.in | D10: 8340184575 | E10: 7.45 | F10: https://drive.google.com/file/d/1njgX8yM21P04_RCJ-rPHIO1284Ue7BJo/view?usp=drive_link | G10: https://drive.google.com/file/d/1oFKkuTGEfncGcIY6bZH-OKDEu3nFyHUy/view?usp=drive_link | H10: Internship | I10: Data Science | J10: 28/04/2026 Tuesday 04:30 PM - 05:00 PM (Data Science) | Nikitakumari | L10: 22f3000107@ds.study.iitm.ac.in
A11: 46131.856 | B11: Taniya Chouhan | C11: 23f2003584@ds.study.iitm.ac.in | D11: 9460844955 | E11: 7.87 | F11: https://drive.google.com/file/d/1XkL6bm4HJuJzc425LqNZMtYKdT5VOlV0/view?usp=sharing | G11: https://drive.google.com/file/d/1jknOGlysI5rhLjr3o2SzcPdTY7r77jgr/view?usp=sharing | H11: Internship | I11: Data Science | J11: 28/04/2026 Tuesday 04:00 PM - 04:30 PM (Data Science) | Karthik | L11: 23f2003584@ds.study.iitm.ac.in
A12: 46131.87 | B12: Achal Deep | C12: 22f3000694@ds.study.iitm.ac.in | D12: 8882475437 | E12: 8.53 | F12: https://drive.google.com/file/d/1dnkJ-vM-XWS0jQYbzdgkCt5cmVFlGiI3/view?usp=sharing | G12: https://drive.google.com/file/d/1j7b48SLkwWMnmm6Lo2z1_Ny8u0_B8t-9/view?usp=sharing | H12: Internship | I12: Data Science | J12: 21/04/2026 Tuesday 04:30 PM - 05:00 PM (Data Science) | Lalit | L12: achaldeep2004@gmail.com
A13: 46131.899 | B13: Anish Maity | C13: 21f3000417@ds.study.iitm.ac.in | D13: 9134034085 | E13: 7.65 | F13: https://drive.google.com/file/d/1ULY_BYlZ1UgPwctDHSz8bWCoPzq_RrPX/view?usp=sharing | G13: https://drive.google.com/file/d/1sbxHBnTKxcolXX5ZDSTZZ6WFVmqWzAl6/view?usp=sharing | H13: Employment | I13: Data Science | J13: 27/04/2026 Monday 04:00 PM - 04:30 PM (Data Science) | Karthik | L13: 21f3000417@ds.study.iitm.ac.in
... A23: 46132.484 | B23: SAMTA RANKA | C23: 23f1001316@ds.study.iitm.ac.in | D23: 7978783934 | E23: 7.63 | F23: https://drive.google.com/file/d/1a9_P4_4C13BWcYyW5bG-IEMsFgXNt3zj/view?usp=sharing | G23: https://drive.google.com/file/d/1QMDxtQbYdYlG5lzo-4ZLU1F2clyuhcT1/view?usp=sharing | H23: Internship | I23: Data Science | J23: 20/04/2026 Monday 04:00 PM - 04:30 PM (Data Science) | Lalit | L23: 23f1001316@ds.study.iitm.ac.in
A24: 46139.935 | B24: Adhyan Mishra | C24: 23f2000260@ds.study.iitm.ac.in | D24: 8368322631 | E24: 7.3 | F24: https://drive.google.com/file/d/1BRFlndqHUXMD5ECEdQj-Vaz-wOBh04Gc/view?usp=drivesdk | G24: https://drive.google.com/file/d/1y9CPtFvjTftiA6BfqmpZ3w_BjaalB8cQ/view?usp=drivesdk | H24: Internship | I24: Programming | K24: 28/04/2026 Tuesday 05:30 PM - 06:00 PM (Programming) | Atul | L24: 23f2000260@ds.study.iitm.ac.in
A25: 46139.958 | B25: Aakash Sharma | C25: 24f2003480@ds.study.iitm.ac.in | D25: 8989607974 | E25: 7.14 | F25: https://docs.google.com/document/d/1zzkUISYcYB0pUsPj9rbD4Le6m0kh__Aji58kZOu7cjs/edit?usp=sharing | G25: https://drive.google.com/file/d/1gwIw3m8TYhK6uAkioCKFTjIv7cFObI1D/view?usp=sharing | H25: Internship | I25: Programming | K25: 28/04/2026 Tuesday 05:00 PM - 05:30 PM (Programming) | Atul | L25: 24f2003480@ds.study.iitm.ac.in
A26: 46141.465 | B26: Muskan Periwal | C26: 22f3001005@ds.study.iitm.ac.in | D26: 6367755955 | E26: 7.24 | F26: https://drive.google.com/file/d/1jRsb5lSEGao48OXi8qeJfleKnSI18ZWP/view?usp=sharing | G26: https://drive.google.com/file/d/1V2ywLMkIvJ7fkdBNgruQmBlnzGxIdJjT/view?usp=sharing | H26: Internship | I26: Data Science | J26: 30/04/2026 Thursday 04:00 PM - 04:30 PM (Data Science) | Nikitakumari | L26: 22f3001005@ds.study.iitm.ac.in
A27: 46141.479 | B27: Rishi Bhatt | C27: 21f1000330@ds.study.iitm.ac.in | D27: 8277097271 | E27: 8.01 | F27: https://drive.google.com/drive/folders/1IkTyfqBjuWGMKnxA0Ib-5-cA8tlohFgb?dmr=1&ec=wgc-drive-%5Bmodule%5D-goto | G27: https://drive.google.com/file/d/1_yUc3ihtrL02hF8Voe2Lb2AMdtkVuQMA/view?usp=drive_link | H27: Employment | I27: Data Science | J27: 01/05/2026 Friday 12:45 PM - 01:00 PM (Data Science) | Lalit | L27: 21f1000330@ds.study.iitm.ac.in
A28: 46142.615 | B28: Nivedita Shill | C28: 24f1001642@ds.study.iitm.ac.in | D28: 9365265655 | E28: 7.12 | F28: https://drive.google.com/file/d/1r2FlywJo2bge72zHu6R5kD0199iY777H/view?usp=sharing | G28: https://drive.google.com/file/d/1D1vKqw-uU4rLGfYUVR7tnFNishemqCUn/view?usp=sharing | H28: Internship | I28: Data Science | J28: 01/05/2026 Friday 12:30 PM - 12:45 PM (Data Science) | Lalit | L28: niveditashill444@gmail.com
A29: 46142.62 | B29: Vaikhari Kanetkar | C29: 22f3000926@ds.study.iitm.ac.in | D29: 8484077935 | E29: 6.5 | F29: https://drive.google.com/file/d/1GX3HJbOFImb5QFxkdt7Be8IU2uKZMAUq/view?usp=drivesdk | G29: https://drive.google.com/file/d/1nzX5rqaapgfqE69VO8J3pi7PxvOxrChr/view?usp=drivesdk | H29: Internship | I29: Data Science | J29: 01/05/2026 Friday 12:15 PM - 12:30 PM (Data Science) | Lalit | L29: 22f3000926@ds.study.iitm.ac.in
A30: 46142.643 | B30: Sneha Dutta | C30: 21f1001697@ds.study.iitm.ac.in | D30: 8017767311 | E30: 7.195 | F30: https://drive.google.com/file/d/12FnWB0j_Ezsh66xPIf2lDDBsnIy2UIbD/view?usp=sharing | G30: https://drive.google.com/file/d/1PE8Ju7_dNpRVATTaeR9sjkKFt8ASdldy/view?usp=sharing | H30: Internship | I30: Data Science | J30: 01/05/2026 Friday 12:00 PM - 12:15 PM (Data Science) | Lalit | L30: 21f1001697@ds.study.iitm.ac.in
A31: 46142.737 | B31: Gautam Seyal | C31: 21f2000646@ds.study.iitm.ac.in | D31: 6005726422 | E31: 6 | F31: https://drive.google.com/file/d/1wkSQwWNfrRR5i0T6_K6dJSoDzhA3RTBA/view?usp=sharing | G31: https://drive.google.com/file/d/1dUY1_cTrZU4mV49hSPcQwKx0Tke2yvN5/view?usp=drive_link | H31: Internship | I31: Data Science | J31: 01/05/2026 Friday 11:45 AM - 12:00 PM (Data Science) | Lalit | L31: 21f2000646@ds.study.iitm.ac.in
A32: 46142.785 | B32: KhushiTiwari | C32: 22f2000364@ds.study.iitm.ac.in | D32: 7667717756 | E32: 6.44 | F32: https://drive.google.com/file/d/1YWHD3jAHOFa5Kaq-FloX-AIujtLq4u0f/view?usp=sharing | G32: https://drive.google.com/drive/home | H32: Internship | I32: Data Science | J32: 01/05/2026 Friday 11:30 AM - 11:45 AM (Data Science) | Lalit | L32: 22f2000364@ds.study.iitm.ac.in
A33: 46142.797 | B33: Dipshikha | C33: 23f2001481@ds.study.iitm.ac.in | D33: 9508492656 | E33: 6.23 | F33: https://drive.google.com/file/d/1nbHBTCuyFVYtJ9DO5U22AeI-cWkBXTe3/view?usp=drive_link | G33: https://drive.google.com/file/d/1J31ZeiohoQ68T0GdXi2rWk5pdjiIt-HP/view?usp=sharing | H33: Internship | I33: Data Science | J33: 01/05/2026 Friday 11:15 AM - 11:30 AM (Data Science) | Lalit | L33: 23f2001481@ds.study.iitm.ac.in

Sheet FR2
A1: Timestamp | B1: Student Name | C1: Student Email | D1: Mobile Number | E1: Overall CGPA | F1: Upload your resume | G1: Upload your progress card. Step 1: Go to Student Dashboard Step 2: Click on the menu on your left side-bar and go to "Documents for Download" section. Step 3: Search for "2025 Sep Progress Card" and download it. Step 4: Convert your resume into a single PDF, upload the PDF to your Google Drive, change the sharing settings to ‘Anyone with the link can view,’ and paste the link below. | H1: Plan | I1: Which domain? | J1: Slots (Timing in IST) – Data Science | K1: Slots (Timing in IST) – Programming
A2: 46100.644 | B2: Niraj Kumar | C2: 21f1006589@ds.study.iitm.ac.in | D2: 9570194524 | E2: 7.14 | F2: https://drive.google.com/file/d/1rZI7-SiZAOB7NUnsO9n68cEl-txaqh7W/view?usp=drive_link | G2: https://drive.google.com/file/d/15mwRkXLr_nCW1QTHNTsoVpOHfm87Bm_E/view?usp=drive_link | H2: Internship | I2: Data Science | J2: 23/03/2026 Monday 04:00 PM - 04:30 PM (Data Science) | Nikitakumari
A3: 46100.646 | B3: muralidhar k | C3: 22f3000528@ds.study.iitm.ac.in | D3: 8885312229 | E3: 7.64 | F3: https://drive.google.com/file/d/1V0lrKfEIRVPJGxFO_eczcKDEDyNgnlrv/view?usp=sharing | G3: https://drive.google.com/file/d/1FQdlztLwEPAvE6VlPvfaIZrD0iEUqtg5/view?usp=sharing | H3: Internship | I3: Data Science | J3: 23/03/2026 Monday 04:30 PM - 05:00 PM (Data Science) | Nikitakumari
A4: 46100.647 | B4: Kalppana S | C4: 23f2000387@ds.study.iitm.ac.in | D4: 7358161922 | E4: 8.07 | F4: https://drive.google.com/file/d/1UuLj2GSfpvm_fyIK9c-z9GjQvWlAExZQ/view?usp=sharing | G4: https://drive.google.com/file/d/1Q5eHi_yiYp0jEq1q23-Feq7_eOk0t8Hk/view?usp=sharing | H4: Internship | I4: Data Science | J4: 22/03/2026 Sunday 06:30 PM - 07:00 PM (Data Science) | Mayur
A5: 46100.648 | B5: Madhan Karthikeyan | C5: 23f3001646@ds.study.iitm.ac.in | D5: 9361951624 | E5: 7.09 | F5: https://drive.google.com/file/d/1Ns_mYzSMTjETrzkrej4xzQtKYtlEWQpI/view?usp=drivesdk | G5: https://drive.google.com/file/d/1SvkkqMmszEemQNIMMjUqRXSbNn160f_8/view?usp=drivesdk | H5: Internship | I5: Data Science | J5: 23/03/2026 Monday 04:30 PM - 05:00 PM (Data Science) | Anamika
A6: 46100.648 | B6: Pinki | C6: 23f2003874@ds.study.iitm.ac.in | D6: 9813743480 | E6: 7.95 | F6: https://drive.google.com/file/d/104nryzwyTS7FFFtk2SRj3W6-gmzFSbvZ/view?usp=sharing | G6: https://drive.google.com/file/d/10Xx36gjUQpW9BReDRIhUKnQZXjNmSbH8/view?usp=sharing | H6: Internship | I6: Data Science | J6: 23/03/2026 Monday 05:00 PM - 05:30 PM (Data Science) | Anamika
A7: 46100.65 | B7: M Harsha Vardhan | C7: 23f3001911@ds.study.iitm.ac.in | D7: 8309365976 | E7: 8.91 | F7: https://drive.google.com/file/d/1dmiW_Ajp-5EDBriIXby6j5QUpu36h7Yp/view?usp=sharing | G7: https://drive.google.com/file/d/130cZHgmpf-W7PUlQJ41WU8osKcXQvxyW/view?usp=sharing | H7: Internship | I7: Data Science | J7: 23/03/2026 Monday 05:30 PM - 06:00 PM (Data Science) | Anamika
A8: 46100.653 | B8: Rishav Kumar | C8: 22f3001352@ds.study.iitm.ac.in | D8: 9142347554 | E8: 7.3 | F8: https://drive.google.com/file/d/1LD_qcJGhcV_7lHjfyh2o0u-X7uwI08jZ/view?usp=drivesdk | G8: https://drive.google.com/file/d/1Mt2IX9ojnCtNiGz30yBc6NqBGaSGAwI5/view?usp=drivesdk | H8: Internship | I8: Data Science | J8: 23/03/2026 Monday 04:00 PM - 04:30 PM (Data Science) | Anamika
A9: 46100.653 | B9: Aditri mandal | C9: 23f3004174@ds.study.iitm.ac.in | D9: 7320010123 | E9: 7.05 | F9: https://drive.google.com/file/d/164rXzQicQDVHlNAU5Ih9xMmFFkaITr-M/view?usp=sharing | G9: https://drive.google.com/file/d/1QOQeKWtuGhF5cwH56HAjkmSv8KR3RIAd/view?usp=sharing | H9: Internship | I9: Data Science | J9: 23/03/2026 Monday 12:00 PM - 12:30 PM (Data Science) | Lalit
A10: 46100.664 | B10: Muskan Periwal | C10: 22f3001005@ds.study.iitm.ac.in | D10: 6367755955 | E10: 7.24 | F10: https://drive.google.com/file/d/1jRsb5lSEGao48OXi8qeJfleKnSI18ZWP/view?usp=sharing | G10: https://drive.google.com/file/d/1V2ywLMkIvJ7fkdBNgruQmBlnzGxIdJjT/view?usp=sharing | H10: Internship | I10: Data Science | J10: 23/03/2026 Monday 12:30 PM - 01:00 PM (Data Science) | Lalit
A11: 46100.675 | B11: Shubham Tiwari | C11: 22f1001934@ds.study.iitm.ac.in | D11: 6394801207 | E11: 7.28 | F11: https://drive.google.com/file/d/1uROuR8Zvz4Gfk2xNV2Yb5MmERV6a3gaA/view?usp=drive_link | G11: https://drive.google.com/file/d/1nSZKXyoo4q1cG94R91V_B5dzxMIgYNhY/view?usp=drive_link | H11: Internship | I11: Data Science | J11: 24/03/2026 Tuesday 12:30 PM - 01:00 PM (Data Science) | Lalit
A12: 46100.689 | B12: Sneha Dutta | C12: 21f1001697@ds.study.iitm.ac.in | D12: 8017767311 | E12: 6.64 | F12: https://drive.google.com/file/d/12FnWB0j_Ezsh66xPIf2lDDBsnIy2UIbD/view?usp=sharing | G12: https://drive.google.com/file/d/1PE8Ju7_dNpRVATTaeR9sjkKFt8ASdldy/view?usp=sharing | H12: Internship | I12: Data Science | J12: 24/03/2026 Tuesday 12:00 PM - 12:30 PM (Data Science) | Lalit
A13: 46100.703 | B13: Anjali Dogra | C13: 22f3001285@ds.study.iitm.ac.in | D13: 9999306403 | E13: 7.45 | F13: https://drive.google.com/file/d/1l6POI80q2n358eFGV2XjZjdVUySqfIpL/view?usp=sharing | G13: https://drive.google.com/file/d/1Q2o7F_CmF2yddPTRNHbfI9ITMt76aQWd/view?usp=sharing | H13: Internship | I13: Data Science | J13: 24/03/2026 Tuesday 11:30 AM - 12:00 PM (Data Science) | Lalit
... A16: 46100.757 | B16: Himanshu Singh | C16: 21f1003259@ds.study.iitm.ac.in | D16: 9140525531 | E16: 7.19 | F16: https://drive.google.com/file/d/1CQqf9-tLTVvGs8VdT9Ne0uoDvpxQO96o/view?usp=sharing | G16: https://drive.google.com/file/d/1omR9TB8LXjUCebNoOM7LI2HMDKebTpkY/view?usp=sharing | H16: Employment | I16: Data Science | J16: 23/03/2026 Monday 11:00 AM - 11:30 AM (Data Science) | Lalit
A17: 46106.663 | B17: ILESHA SRIVASTAVA | C17: 23f2004210@ds.study.iitm.ac.in | D17: 9974747348 | E17: 8.35 | F17: https://drive.google.com/file/d/1Fe5GCN7CWf7JaXJdzOHNAxQMh2JZCjcx/view?usp=sharing | G17: https://drive.google.com/file/d/1wBEQXKtbguYP0k9U84boTdmxWOV7o3rx/view?usp=sharing | H17: Internship | I17: Programming | K17: 30/03/2026 Monday 04:30 PM - 05:00 PM (Programming) | Arup
A18: 46106.667 | B18: Ananya Chakraborty | C18: 21f2000372@ds.study.iitm.ac.in | D18: 7439629745 | E18: 6.87 | F18: https://drive.google.com/file/d/1AZDapGfVcCNex0zn6MrXSjWbHnGstavW/view?usp=sharing | G18: https://drive.google.com/file/d/1wiIuK53QB5yeHQITI8lREGsZrsDXw_8D/view?usp=sharing | H18: Internship | I18: Programming | K18: 30/03/2026 Monday 04:00 PM - 04:30 PM (Programming) | Arup
A19: 46106.695 | B19: Rishav Kumar | C19: 23f1003150@ds.study.iitm.ac.in | D19: 9546667831 | E19: 7.03 | F19: https://drive.google.com/file/d/1q9sr5vpfPJMEbxg4uZ4au1Pmt8hYluRA/view?usp=drivesdk | G19: https://drive.google.com/file/d/1q8Qak1ATuHxIOt0XCo1RkZ3Toe2mzhUe/view?usp=drivesdk | H19: Internship | I19: Programming | K19: 28/03/2026 Saturday 04:30 PM - 05:00 PM (Programming) | Arup
A20: 46106.752 | B20: Nitin yadav | C20: 23f2003203@ds.study.iitm.ac.in | D20: 8588067701 | E20: 6.73 | F20: https://drive.google.com/file/d/1xX7x1mouzmy5JOdoVJATlD7TG4ibZhab/view?usp=sharing | G20: https://drive.google.com/file/d/1NZ-fPg5ICHO_gCvBcDgTJFTal9VuTQa0/view?usp=sharing | H20: Internship | I20: Programming | K20: 28/03/2026 Saturday 04:00 PM - 04:30 PM (Programming) | Arup
A21: 46106.773 | B21: S Radhesree | C21: 22f2001565@ds.study.iitm.ac.in | D21: 8486028178 | E21: 6.86 | F21: https://drive.google.com/file/d/1U_gfc9Bk7DtVxKrDg8K4FXcu_Xthr-Xv/view?usp=sharing | G21: https://drive.google.com/file/d/1TBcEzfYBGWUnlm4EyHZaBqmCsDf8sxHM/view?usp=sharing | H21: Internship | I21: Programming | K21: 26/03/2026 Thursday 04:00 PM - 04:30 PM (Programming) | Arup
A22: 46106.794 | B22: Abhishek kumar | C22: 23f1003112@ds.study.iitm.ac.in | D22: 9162809149 | E22: 8.57 | F22: https://drive.google.com/file/d/1pFEYk-ChoshPWyOt9AqfMsC4gOFXHibW/view?usp=sharing | G22: https://drive.google.com/file/d/1abvdrpe4oviGiLL8_HzGS2TB9m-P8QFO/view?usp=sharing | H22: Employment | I22: Programming | K22: 26/03/2026 Thursday 04:30 PM - 05:00 PM (Programming) | Arup
A23: 46106.796 | B23: Vivekanand kumawat | C23: 23f2004577@ds.study.iitm.ac.in | D23: 9828251124 | E23: 7.41 | F23: https://drive.google.com/file/d/1jG6iLvelrosKIBIfHPy8tn-SnFLLlTRb/view?usp=sharing | G23: https://drive.google.com/file/d/1TtGH5gxasCbRzfmW6iywlCuAKyQarzZl/view | H23: Internship | I23: Programming | K23: 26/03/2026 Thursday 04:30 PM - 05:00 PM (Programming) | Atul
A24: 46107.566 | B24: Akula Geetha Maheswari | C24: 21f3000254@ds.study.iitm.ac.in | D24: 7661838282 | E24: 8.4 | F24: https://drive.google.com/file/d/1fKlN6yKcK2YJ7fCyZ1iULPsoSf7wzDnw/view?usp=sharing | G24: https://drive.google.com/file/d/1-aVk61y8QHF2cpQL-5dFxAFw7DR48WhC/view?usp=sharing | H24: Employment | I24: Data Science | J24: 01/04/2026 Wednesday 07:30 PM - 08:00 PM (Data Science) | Jimmi
A25: 46107.583 | B25: Harsh Patel | C25: 22f1001058@ds.study.iitm.ac.in | D25: 8237960551 | E25: 6.45 | F25: https://drive.google.com/file/d/1-wsCVyPgfCy1OCx4vpdCVGW3uTfKHuPO/view?usp=sharing | G25: https://drive.google.com/file/d/1JAZ9xQoIKz8mrAGKVlhlRivzibY_Zq1Z/view?usp=sharing | H25: Internship | I25: Data Science | J25: 31/03/2026 Tuesday 04:30 PM - 05:00 PM (Data Science) | Anamika
A26: 46107.594 | B26: Ashish Bajaj | C26: 21f3001304@ds.study.iitm.ac.in | D26: 9826229443 | E26: 7.61 | F26: https://drive.google.com/file/d/1GMZnDMqrezL6PvnDBAKVDT6pfZEHGZRa/view?usp=sharing | G26: https://drive.google.com/file/d/1bQ6aDMlWKb0RdD2TQVW8mP-laTjv665G/view?usp=sharing | H26: Employment | I26: Data Science | J26: 31/03/2026 Tuesday 04:00 PM - 04:30 PM (Data Science) | Anamika
A27: 46107.603 | B27: Anagha Choudhary | C27: 21f1003066@ds.study.iitm.ac.in | D27: 7262972730 | E27: 6.9 | F27: https://drive.google.com/file/d/1Za77pmaABHQhNtKC-ItJWzxih5un-E6o/view?usp=sharing | G27: https://drive.google.com/file/d/1Za77pmaABHQhNtKC-ItJWzxih5un-E6o/view?usp=sharing | H27: Internship | I27: Data Science | J27: 01/04/2026 Wednesday 07:00 PM - 07:30 PM (Data Science) | Jimmi
A28: 46107.603 | B28: Aarush Agarwal | C28: 22f3001115@ds.study.iitm.ac.in | D28: 8700524258 | E28: 8.06 | F28: https://drive.google.com/file/d/10UlKudGcl6GfqwSTKbeNsQyOCjrMph_6/view?usp=sharing | G28: https://drive.google.com/file/d/13G0RrFmjFveffWgdVLhkCQDDtxb_oicV/view?usp=sharing | H28: Internship | I28: Data Science | J28: 31/03/2026 Tuesday 11:45 AM - 12:00 PM (Data Science) | Lalit
A29: 46107.605 | B29: Paramananda Samantara | C29: 22f3000935@ds.study.iitm.ac.in | D29: 8690625704 | E29: 8.05 | F29: https://drive.google.com/file/d/1mpqWz-8WKBy2P8QJuVBRfALypfGGKaXM/view?usp=sharing | G29: https://drive.google.com/file/d/1T7H0GAlEUpZTeMGFSMH79GN4d8Q2pBfi/view?usp=sharing | H29: Internship | I29: Data Science | J29: 30/03/2026 Monday 11:30 AM - 11:45 AM (Data Science) | Lalit
A30: 46107.606 | B30: Ritik Yadav | C30: 23f2004634@ds.study.iitm.ac.in | D30: 9350957047 | E30: 7.31 | F30: https://drive.google.com/file/d/1SEX7TP0yIDthFcTAbfEem16TvQWCOXvB/view?usp=sharing | G30: https://drive.google.com/file/d/19ttHHHHE-JCq1lQV9NVX1zERzjKihUfF/view?usp=sharing | H30: Internship | I30: Data Science | J30: 27/03/2026 Friday 12:45 PM - 01:00 PM (Data Science) | Lalit
A31: 46107.606 | B31: Hariom Kashyap | C31: 21f2000584@ds.study.iitm.ac.in | D31: 8544032450 | E31: 6.41 | F31: https://drive.google.com/drive/folders/1xZNIiTGuyv1Hszfso4rbI60U3Gfne1TF?usp=drive_link | G31: https://drive.google.com/drive/folders/1HwInnQ0S1PiIApES6OAFeyHT46fw62fe?usp=sharing | H31: Internship | I31: Data Science | J31: 31/03/2026 Tuesday 12:30 PM - 12:45 PM (Data Science) | Lalit
A32: 46107.608 | B32: Prasoon Shukla | C32: 23f3003434@ds.study.iitm.ac.in | D32: 6383130781 | E32: 8.18 | F32: https://drive.google.com/file/d/1VgOgZrIJA09gql0hZwAwVctf3XX7h8J2/view?usp=sharing | G32: https://drive.google.com/file/d/1uc0kOGcffBKR3PxD5CttyeTlDKyeBJBe/view?usp=sharing | H32: Internship | I32: Data Science | J32: 31/03/2026 Tuesday 12:45 PM - 01:00 PM (Data Science) | Lalit
A33: 46107.61 | B33: Hitesh Binjrawat | C33: 22f2001255@ds.study.iitm.ac.in | D33: 9306019147 | E33: 7.79 | F33: https://drive.google.com/file/d/1fuU2GPnHRbfjlikx2z7_KdTiFDrdvrYH/view?usp=drive_link | G33: https://drive.google.com/file/d/1M1oUOgDYgU1NnWfTVY0-cg-hA2Bsk2cK/view?usp=sharinghttps://drive.google.com/file/d/1fuU2GPnHRbfjlikx2z7_KdTiFDrdvrYH/view?usp=drive_link | H33: Employment | I33: Data Science | J33: 30/03/2026 Monday 12:45 PM - 01:00 PM (Data Science) | Lalit
A34: 46107.612 | B34: Apoorva Gupta | C34: 21f1003639@ds.study.iitm.ac.in | D34: 9953757794 | E34: 8.86 | F34: https://drive.google.com/file/d/1z-ORuucTnq0AW1FMQCKLuJh0Qx1a9Vnv/view?usp=sharing | G34: https://drive.google.com/file/d/1XnZmgVybvAVjzXpWT2jR3Gb79Rd0angb/view?usp=sharing | H34: Employment | I34: Data Science | J34: 31/03/2026 Tuesday 12:15 PM - 12:30 PM (Data Science) | Lalit
A35: 46107.614 | B35: Achal Deep | C35: 22f3000694@ds.study.iitm.ac.in | D35: 8882475437 | E35: 8.53 | F35: https://drive.google.com/drive/folders/1N0hhJZcFLQ_f1OzISYIga6gtNzIKs_EU?usp=sharing | G35: https://drive.google.com/file/d/1j7b48SLkwWMnmm6Lo2z1_Ny8u0_B8t-9/view?usp=sharing | H35: Internship | I35: Data Science | J35: 31/03/2026 Tuesday 11:00 AM - 11:15 AM (Data Science) | Lalit
... A44: 46107.655 | B44: N M PRANITHA | C44: 22f1000765@ds.study.iitm.ac.in | D44: 6381288446 | E44: 6.94 | F44: https://drive.google.com/file/d/1-8KyRYQUNdewcqOHKW2yK-tIYuKqR-rE/view?usp=drive_link | G44: https://drive.google.com/file/d/1Tp61WCJSWJe6EX18N6Q2ftvx_UVu1HPv/view?usp=drive_link | H44: Internship | I44: Data Science | J44: 30/03/2026 Monday 11:15 AM - 11:30 AM (Data Science) | Lalit
A45: 46107.658 | B45: Pingaksha Sahay | C45: 23f2003519@ds.study.iitm.ac.in | D45: 9631908675 | E45: 9.11 | F45: https://drive.google.com/drive/folders/14kZIBPyTEeQJMXAt5__5ukHL2_XZHaoR?usp=sharing | G45: https://drive.google.com/file/d/1AR7tccXE5zXs4J0FudRDGtEUVqHXP0f2/view?usp=sharing | H45: Internship | I45: Programming | K45: 01/04/2026 Wednesday 04:00 PM - 04:30 PM (Programming) | Atul
A46: 46107.668 | B46: Rajeev Kumar bhagat | C46: 21f3001527@ds.study.iitm.ac.in | D46: 7903766709 | E46: 8.1 | F46: https://drive.google.com/file/d/1FQUSt5CtWDI-pvNgKpFC7bPduiVjYwEX/view?usp=drivesdk | G46: https://drive.google.com/file/d/1WhRX0uocF9EEshcS6jD7M6Cf7XSwXcrN/view?usp=drivesdk | H46: Internship | I46: Data Science | J46: 30/03/2026 Monday 11:00 AM - 11:15 AM (Data Science) | Lalit
A47: 46107.679 | B47: Umesh Aradhya P | C47: 21f1004720@ds.study.iitm.ac.in | D47: 9380320085 | E47: 6.4 | F47: https://drive.google.com/file/d/1ISz5lKeh1EDPDqIsrEBqac2OTG9rr_QK/view?usp=drivesdk | G47: https://drive.google.com/file/d/1yfR8btU-5LRB3G7uUdxlZmA3kMD3g4jQ/view?usp=drivesdk | H47: Employment | I47: Data Science | J47: 27/03/2026 Friday 11:00 AM - 11:15 AM (Data Science) | Lalit
A48: 46107.679 | B48: Swati Jain | C48: 21f3000759@ds.study.iitm.ac.in | D48: 8697001351 | E48: 8.35 | F48: https://drive.google.com/drive/folders/1a0jYoxINKTim4WrX6f6C9SisM7xmz-Vw?usp=sharing | G48: https://drive.google.com/file/d/1r-SADzmGOP2h2iO4neVkBlkEbUK3lk0B/view?usp=sharing | H48: Internship | I48: Programming | K48: 02/04/2026 Thursday 04:00 PM - 04:30 PM (Programming) | Atul
A49: 46107.684 | B49: B Sarveshraj | C49: 23f2000592@ds.study.iitm.ac.in | D49: 8870129519 | E49: 7.12 | F49: https://drive.google.com/file/d/1QvorqAKU8pCe3XomlnOdDeynMj-BBiRO/view?usp=sharing | G49: https://drive.google.com/file/d/1rw7xj5WLGl8GqftwZNKPzbzSnToZ2laD/view?usp=drive_link | H49: Internship | I49: Programming | K49: 01/04/2026 Wednesday 07:30 PM - 08:00 PM (Programming) | Shubhammaurya
A50: 46107.719 | B50: Rahul Maurya | C50: 23f1002653@ds.study.iitm.ac.in | D50: 6306330760 | E50: 8.37 | F50: https://drive.google.com/file/d/1t-0MOuczF_qheJwIGqblM_3Cd_hXbws9/view?usp=sharing | G50: https://drive.google.com/file/d/1tBADokdx1igwsoMnfKvi8l2GCax7uxqM/view?usp=sharing | H50: Internship | I50: Programming | K50: 01/04/2026 Wednesday 04:30 PM - 05:00 PM (Programming) | Atul
...

Sheet FR4
A1: Timestamp | B1: Student Name | C1: Student Email | D1: Mobile Number | E1: Overall CGPA | F1: Upload your resume | G1: Upload your progress card. Step 1: Go to Student Dashboard Step 2: Click on the menu on your left side-bar and go to "Documents for Download" section. Step 3: Search for "2025 Sep Progress Card" and download it. Step 4: Convert your resume into a single PDF, upload the PDF to your Google Drive, change the sharing settings to ‘Anyone with the link can view,’ and paste the link below. | H1: Which domain? | I1: Slots (Timing in IST) – Data Science | J1: Slots (Timing in IST) – Programming | K1: Plan
A2: 46099.547 | B2: Harshit Tiwari | C2: 22f3002587@ds.study.iitm.ac.in | D2: 7897049891 | E2: 6.91 | F2: https://drive.google.com/file/d/1hU4RGh546o0MXIjwKlOo3rOhLDbMcP8U/view?usp=sharing | G2: https://drive.google.com/file/d/19Pyk_7vqARDAez5hbznGAdhnLNJDOs9h/view?usp=sharing | H2: Data Science | I2: 19/03/2026 Thursday 12:30 PM - 01:00 PM (Data Science) | Lalit
A3: 46099.554 | B3: Paramananda Samantara | C3: 22f3000935@ds.study.iitm.ac.in | D3: 8690625704 | E3: 8.05 | F3: https://drive.google.com/file/d/1WGoINZDVxJxlAgrYTzNugmrlvB5HW1Np/view?usp=sharing | G3: https://drive.google.com/file/d/1T7H0GAlEUpZTeMGFSMH79GN4d8Q2pBfi/view?usp=sharing | H3: Data Science | I3: 20/03/2026 Friday 07:00 PM - 07:30 PM (Data Science) | Mayur
A4: 46099.556 | B4: Aryan Thakur | C4: 23f1000966@ds.study.iitm.ac.in | D4: 8287770250 | E4: 7.52 | F4: https://drive.google.com/file/d/1zA06ykxUNA1JtZ1u3nE5qljbkrn88AH3/view?usp=sharing | G4: https://drive.google.com/file/d/1aCN3RnxdiyZ6iTOKy05d8oSXAy6Vbn7J/view?usp=sharing | H4: Data Science | I4: 20/03/2026 Friday 07:30 PM - 08:00 PM (Data Science) | Mayur
A5: 46099.559 | B5: Lakshya Luv Mimani | C5: 22f1001082@ds.study.iitm.ac.in | D5: 7076245448 | E5: 8.18 | F5: https://drive.google.com/file/d/1z0Lv5kMNniBXoqPCv7TexQ2BbKIEHlll/view?usp=sharing | G5: https://drive.google.com/file/d/1HI9pIHt1v1dSL7edw1t6CyHIdFUKD01r/view?usp=sharing | H5: Programming | J5: 19/03/2026 Thursday 04:30 PM - 05:00 PM (Programming) | Atul
A6: 46099.565 | B6: Ravisha Shrivastava | C6: 22f3003015@ds.study.iitm.ac.in | D6: 8085511663 | E6: 6.94 | F6: https://drive.google.com/file/d/18rVG9IiKDx39PVTBMPbV73bnY3cc3bOl/view?usp=sharing | G6: https://drive.google.com/file/d/1H6Q_khePBI42DV7irib2apiFWq37ebXE/view?usp=sharing | H6: Data Science | I6: 19/03/2026 Thursday 06:00 PM - 06:30 PM (Data Science) | Lalit
A7: 46099.565 | B7: Nivedita Shill | C7: 24f1001642@ds.study.iitm.ac.in | D7: 9365265655 | E7: 7.12 | F7: https://drive.google.com/file/d/16hi3hj0XinFFgKv5ssx1pd0RrQD7Izic/view?usp=sharing | G7: https://drive.google.com/file/d/1D1vKqw-uU4rLGfYUVR7tnFNishemqCUn/view?usp=sharing | H7: Data Science | I7: 19/03/2026 Thursday 05:30 PM - 06:00 PM (Data Science) | Lalit
A8: 46099.569 | B8: Vaidisha P Shetty | C8: 23f3001196@ds.study.iitm.ac.in | D8: 7338315216 | E8: 9.01 | F8: https://drive.google.com/file/d/1AqcKEXOXC2KW1fUukE_P4rgdHtEKsCvH/view | G8: https://drive.google.com/file/d/1uTCSi8QAZyaNhdNKflSpU1exP38jZmvO/view?usp=drive_link | H8: Programming | J8: 19/03/2026 Thursday 04:00 PM - 04:30 PM (Programming) | Atul
A9: 46099.575 | B9: Pardhiv Nukasani | C9: 23f3004115@ds.study.iitm.ac.in | D9: 9121181429 | E9: 7.35 | F9: https://drive.google.com/drive/folders/1199vmxAOAw3V7P3-L7KBt9YgmHE-c0iJ?usp=sharing | G9: https://drive.google.com/file/d/1m28anVmeMk94rr4T04G-Zhb8E2v8oxOo/view?usp=sharing | H9: Programming | J9: 20/03/2026 Friday 04:30 PM - 05:00 PM (Programming) | Arup
A10: 46099.581 | B10: Rohit Prajapat | C10: 22f1001536@ds.study.iitm.ac.in | D10: 9119292553 | E10: 6.9 | F10: https://drive.google.com/file/d/14_CdesZ2rvN6tW7-A2BwDJVPYnH6vlJ6/view?usp=sharing | G10: https://drive.google.com/file/d/1qXau8y-SK8CJ0fhmlP4j8hdB0XeilhCB/view?usp=sharing | H10: Data Science | I10: 19/03/2026 Thursday 05:00 PM - 05:30 PM (Data Science) | Lalit
A11: 46099.587 | B11: Nitya Sharma | C11: 23f3003687@ds.study.iitm.ac.in | D11: 8950474501 | E11: 7.55 | F11: https://drive.google.com/file/d/1ZFzqYbqENYUFZfHtw8O9ZTzXCFf_gXuV/view?usp=sharing | G11: https://drive.google.com/file/d/1ie85Cs5Wya4qy8ZfeNAp-lGHXTqV3Rbp/view?usp=sharing | H11: Data Science | I11: 19/03/2026 Thursday 11:30 AM - 12:00 PM (Data Science) | Lalit
A12: 46099.591 | B12: Aviral Choudhary | C12: 23f3004412@ds.study.iitm.ac.in | D12: 9877483716 | E12: 8.26 | F12: https://drive.google.com/file/d/171KQ7AqGd-gyj108njMdpCyesKdugyBJ/view?usp=sharing | G12: https://drive.google.com/file/d/1k8faK3bMy1ZWvJjkUKFf1nU5qRIAMQsj/view?usp=sharing | H12: Data Science | I12: 19/03/2026 Thursday 04:30 PM - 05:00 PM (Data Science) | Lalit
A13: 46099.647 | B13: Amisha Mishra | C13: 22f1000938@ds.study.iitm.ac.in | D13: 7905521531 | E13: 8.34 | F13: https://drive.google.com/file/d/1oLIi3BWHdXg_J9eWbqMSdSWy0BXJisIt/view?usp=sharing | G13: https://drive.google.com/file/d/1h8fqqACdfjbxqk3SuoNW39HJuQoEpAh6/view?usp=sharing | H13: Data Science | I13: 19/03/2026 Thursday 12:00 PM - 12:30 PM (Data Science) | Lalit
A14: 46099.668 | B14: Taniya Chouhan | C14: 23f2003584@ds.study.iitm.ac.in | D14: 9460844955 | E14: 7.87 | F14: https://drive.google.com/file/d/1XkL6bm4HJuJzc425LqNZMtYKdT5VOlV0/view?usp=sharing | G14: https://drive.google.com/file/d/1jknOGlysI5rhLjr3o2SzcPdTY7r77jgr/view?usp=sharing | H14: Data Science | I14: 19/03/2026 Thursday 11:00 AM - 11:30 AM (Data Science) | Lalit
A15: 46099.885 | B15: Atul Mishra | C15: 23f2001262@ds.study.iitm.ac.in | D15: 9717510230 | E15: 7.54 | F15: https://drive.google.com/file/d/1iHzQigATsVVWtYvYPBx6MTi0Vy-_4qI8/view?usp=drive_link | G15: https://drive.google.com/file/d/1LUWU7KY2EPm0ug60MGROJdoFgj3Mw16T/view?usp=drive_link | H15: Programming | J15: 20/03/2026 Friday 04:30 PM - 05:00 PM (Programming) | Atul

Sheet FR0
A1: Timestamp | B1: Student Name | C1: Student Email | D1: Mobile Number | E1: Overall CGPA | F1: Upload your resume | G1: Upload your progress card. Step 1: Go to Student Dashboard Step 2: Click on the menu on your left side-bar and go to "Documents for Download" section. Step 3: Search for "2025 Sep Progress Card" and download it. Step 4: Convert your resume into a single PDF, upload the PDF to your Google Drive, change the sharing settings to ‘Anyone with the link can view,’ and paste the link below. | H1: Which domain? | I1: Slots (Timing in IST) – Data Science - Internship | J1: Slots (Timing in IST) – Data Science - Employment | K1: Slots (Timing in IST) – Programming - Internship | L1: Slots (Timing in IST) – Programming - Employment
A2: 46076.646 | B2: Parveen | C2: 21f3001560@ds.study.iitm.ac.in | D2: 9896797618 | E2: 7.84 | F2: https://drive.google.com/file/d/1ICl4XvnvDVaULmKz_QtIpuT0kIcJ7JFD/view?usp=drive_link | G2: https://drive.google.com/file/d/104YvqGild8Vt808vVVGOTIsyetOmMifL/view?usp=drive_link | H2: Data Science - Internship | I2: 24/02/2026 Tuesday 06:00 PM - 06:30 PM (Data Science) | Lalit
A3: 46076.652 | B3: Hemlata Mahawar | C3: 23f1001797@ds.study.iitm.ac.in | D3: 6377423582 | E3: 7.79 | F3: https://drive.google.com/file/d/1nqg7XV4IOeYGBi_FvAFJf-ebhA5alDUF/view?usp=sharing | G3: https://drive.google.com/file/d/1OBXuDm1nYAPG9Cxwx-5Lnx0Ont2-k6uH/view?usp=sharing | H3: Data Science - Internship | I3: 25/02/2026 Wednesday 06:00 PM - 06:30 PM (Data Science) | Lalit
A4: 46076.658 | B4: Deepak singh | C4: 22f3001778@ds.study.iitm.ac.in | D4: 9999482864 | E4: 8.02 | F4: https://drive.google.com/file/d/1JPurK8Ge1SfIzFUGmCdOb9qxw92ZfV0o/view?usp=sharing | G4: https://drive.google.com/file/d/1l31UUR3Sfkcuvgapc01Qp2Q5MYuSEy2J/view?usp=sharing | H4: Data Science - Internship | I4: 24/02/2026 Tuesday 06:30 PM - 07:00 PM (Data Science) | Lalit
A5: 46076.663 | B5: yogaswetha sanjaygandhi | C5: 23f2000098@ds.study.iitm.ac.in | D5: 9629958443 | E5: 6.91 | F5: https://docs.google.com/document/d/1GM-rbGSFSwRbcBjh9naWdoBGLBKlgElz/edit?usp=sharing&ouid=109871065382861790898&rtpof=true&sd=true | G5: https://drive.google.com/file/d/16JeH8-awyX4uUeDENa1aiKvKwMdXa8Lz/view?usp=sharing | H5: Data Science - Internship | I5: 25/02/2026 Wednesday 06:30 PM - 07:00 PM (Data Science) | Lalit
A6: 46076.67 | B6: Sathvik V | C6: 22f2001468@ds.study.iitm.ac.in | D6: 8431003061 | E6: 7.11 | F6: https://drive.google.com/file/d/1v4BoGSc-3JFI_xYJQ8bZcuE7Uy3lA4pU/view?usp=drive_link | G6: https://drive.google.com/file/d/1G7PFQvTG4FuzTuV-n-NXnXMALFKf-d95/view?usp=drive_link | H6: Data Science - Employment | J6: 26/02/2026 Thursday 06:30 PM - 07:00 PM (Data Science) | Lalit
A7: 46077.402 | B7: udghosh rao | C7: 24f2000612@ds.study.iitm.ac.in | D7: 9636039611 | E7: 7.45 | F7: https://drive.google.com/file/d/1N-2uWCwCBQE-sEJjsZ_O3ThlNA0e_CYK/view?usp=sharing | G7: https://drive.google.com/file/d/1DMgWHobfoT7XLdSqrgqxj5gczv_cJzxY/view?usp=sharing | H7: Data Science - Internship | I7: 26/02/2026 Thursday 06:00 PM - 06:30 PM (Data Science) | Lalit
A8: 46082.864 | B8: Karan Shrivastava | C8: 22f2001062@ds.study.iitm.ac.in | D8: 7321969871 | E8: 7.3 | F8: https://drive.google.com/file/d/1NNWuU0gOL065yEIta_yVeyBUeMuOJP0G/view?usp=sharing | G8: https://drive.google.com/file/d/17RfAzrZqCFU2b4LJqzrN9Y7sYQlrLqSI/view?usp=sharing | H8: Data Science - Internship | I8: 02/03/2026 Monday 04:00 PM - 04:30 PM (Data Science) | Jimmi
A9: 46082.864 | B9: Shreya Aggarwal | C9: 23f2000566@ds.study.iitm.ac.in | D9: 8527657733 | E9: 8.9 | F9: https://drive.google.com/file/d/1hWTZlzELzDEg5SpqTpjualIubRVzBhay/view?usp=sharing | G9: https://drive.google.com/file/d/1xPbr5zqiGkiw3XDDHPB8AcwS-eLEJoRg/view?usp=sharing | H9: Data Science - Internship | I9: 02/03/2026 Monday 04:30 PM - 05:00 PM (Data Science) | Jimmi
A10: 46082.871 | B10: Kanishk | C10: 22f1000624@ds.study.iitm.ac.in | D10: 7904645891 | E10: 6.4 | F10: https://drive.google.com/file/d/1NHxqrLSswufWnvMwJr6vmqDFfzhdz8HF/view?usp=drivesdk | G10: https://drive.google.com/file/d/1t5eyWCJourpwjcegCgZVxyvaH_x10iIX/view?usp=drivesdk | H10: Data Science - Employment | J10: 05/03/2026 Thursday 06:30 PM - 07:00 PM (Data Science) | Nikita
A11: 46080.693 | B11: Ashish Al Rashid | C11: 22f1001551@ds.study.iitm.ac.in | D11: 9585058822 | E11: 6.49 | F11: https://drive.google.com/file/d/1R71UwJmqYWgTQTXvBUpLBcaK39eH2Mex/view?usp=sharing | G11: https://drive.google.com/file/d/1E7NuH_0XkpXQKRftBU7L6LAHKNwX3hzf/view?usp=sharing | H11: Programming - Internship | K11: 03/03/2026 Tuesday 04:00 PM - 04:30 PM (Programming) | Satyanarayana
A12: 46082.864 | B12: Ravi Teja Ravipati | C12: 22f1000776@ds.study.iitm.ac.in | D12: 9014215334 | E12: 7.28 | F12: https://drive.google.com/file/d/15nSUCe9-4oKLb0yErT-dhCP0Z_yw6eea/view?usp=drivesdk | G12: https://drive.google.com/file/d/1T1YzqXUiw2G_k2nVdtN3Wuzmhib66-oe/view?usp=drivesdk | H12: Data Science - Employment | J12: 05/03/2026 Thursday 11:00 AM - 11:30 AM (Data Science) | Lalit
A13: 46080.721 | B13: Pranesh Kumar | C13: 23f2004247@ds.study.iitm.ac.in | D13: 9798724149 | E13: 7.22 | F13: https://drive.google.com/file/d/1iuASNHabbR_DsJB8fkO3Vrua07sY83wl/view?usp=sharing | G13: https://drive.google.com/file/d/1NpKBYx8hiJAW2AfznpwoD5keALd1N-M5/view?usp=sharing | H13: Programming - Internship | K13: 04/03/2026 Wednesday 05:00 PM - 05:30 PM (Programming) | Arup
A14: 46080.969 | B14: Ankit Kuniyal | C14: 23f2004089@ds.study.iitm.ac.in | D14: 7017129138 | E14: 6.88 | F14: https://drive.google.com/file/d/1MoPraEtuP2LSaC-klZ5p3MViEMFwFuN8/view?usp=sharing | G14: https://drive.google.com/file/d/1abW16VqQVyP1kvZH5b_NqOI8VoDcjD7G/view?usp=sharing | H14: Programming - Internship | K14: 04/03/2026 Wednesday 05:30 PM - 06:00 PM (Programming) | Arup
A15: 46081.41 | B15: Aaryan Choudhary | C15: 23f2003700@ds.study.iitm.ac.in | D15: 9929586989 | E15: 7.19 | F15: https://drive.google.com/file/d/1uuZ5tbpn21sINUN4LwdVacaDh5Y-rd2y/view?usp=sharing | G15: https://drive.google.com/file/d/1XYP8sSL8nmIZCWO_OFPQsXV2tk79_uag/view?usp=sharing | H15: Programming - Internship | K15: 04/03/2026 Wednesday 04:30 PM - 05:00 PM (Programming) | Arup
A16: 46081.497 | B16: Aman Prakash | C16: 22f3001090@ds.study.iitm.ac.in | D16: 7903410884 | E16: 8.43 | F16: https://drive.google.com/file/d/1aVnjKF4Xb0GkXYEI-5qNV4R0EOyRlnQU/view?usp=drive_link | G16: https://drive.google.com/file/d/1Cuts0agkUm3AvyRC3BmvE0Nh676zk_sP/view?usp=drive_link | H16: Programming - Internship | K16: 04/03/2026 Wednesday 04:00 PM - 04:30 PM (Programming) | Arup
A17: 46081.642 | B17: Tushar Gautam | C17: 24f1000182@ds.study.iitm.ac.in | D17: 8810475697 | E17: 6.96 | F17: https://drive.google.com/file/d/1wrhTefPDTSAqr6u3qniVKA0QHU8f48Ft/view?usp=drivesdk | G17: https://drive.google.com/file/d/1zaT8ZJ2jJHPAfeKp2TSEiXos49xSNRXY/view?usp=drivesdk | H17: Programming - Internship | K17: 02/03/2026 Monday 04:00 PM - 04:30 PM (Programming) | Arup
A18: 46082.866 | B18: Anjali Dogra | C18: 22f3001285@ds.study.iitm.ac.in | D18: 9999306403 | E18: 7.45 | F18: https://drive.google.com/file/d/1aMLEI-rtz_wannnKUXAPfRpMYgGQiDwK/view?usp=sharing | G18: https://drive.google.com/file/d/1Q2o7F_CmF2yddPTRNHbfI9ITMt76aQWd/view?usp=sharing | H18: Data Science - Internship | I18: 04/03/2026 Wednesday 04:00 PM - 04:30 PM (Data Science) | Anamika
A19: 46082.89 | B19: Rasiga. B | C19: 23f2005694@ds.study.iitm.ac.in | D19: 9789083613 | E19: 7.33 | F19: https://drive.google.com/file/d/1tI5EhclzZ4EqDO9mQ9oH59xpeoHrPi0W/view?usp=sharing | G19: https://drive.google.com/file/d/1qltq4fn_R_v5Alk4TOPjADM1IH9iywVK/view?usp=sharing | H19: Data Science - Internship | I19: 03/03/2026 Tuesday 04:00 PM - 04:30 PM (Data Science) | Anamika
A20: 46082.889 | B20: Maan Kaur | C20: 22f3002399@ds.study.iitm.ac.in | D20: 7814669526 | E20: 7.5 | F20: https://drive.google.com/drive/folders/1eBVpdlzAbDuP_u8yBM4SIjU-AT31LukX | G20: https://drive.google.com/drive/folders/1eBVpdlzAbDuP_u8yBM4SIjU-AT31LukX | H20: Data Science - Internship | I20: 03/03/2026 Tuesday 04:30 PM - 05:00 PM (Data Science) | Anamika
A21: 46082.859 | B21: Archit Samvart | C21: 22f3001741@ds.study.iitm.ac.in | D21: 8986862305 | E21: 8.38 | F21: https://drive.google.com/file/d/18Y0sj7qO0JsrpnA_cRq4iz-n4CgXTk9A/view?usp=drivesdk | G21: https://drive.google.com/file/d/1ciyZhjlLT62fg_i5P7zcQ-wwHqk7UtNb/view?usp=drivesdk | H21: Data Science - Internship | I21: 03/03/2026 Tuesday 07:00 PM - 07:30 PM (Data Science) | Jimmi
A22: 46082.972 | B22: pallapu caleb kumar | C22: 23f1002849@ds.study.iitm.ac.in | D22: 9908817990 | E22: 7.33 | F22: https://drive.google.com/file/d/1jvI_-bHWQqiQ58z1dznL7MfKuL06pfRe/view?usp=sharing | G22: https://drive.google.com/file/d/1x8ecInKHkeagvXoepD0k3jwmyKaH8hkk/view?usp=sharing | H22: Data Science - Internship | I22: 02/03/2026 Monday 07:00 PM - 07:30 PM (Data Science) | Aniruddha
A23: 46082.866 | B23: Ashish Raj | C23: 22f3000982@ds.study.iitm.ac.in | D23: 7677242570 | E23: 8.84 | F23: https://drive.google.com/file/d/1_QVEclg4C78jyyehki58PwxhrZA1woPY/view?usp=sharing | G23: https://drive.google.com/file/d/1KbuiScmljFGOkujjana965h2g2PgLmkA/view?usp=sharing | H23: Data Science - Internship | I23: 04/03/2026 Wednesday 04:30 PM - 05:00 PM (Data Science) | Anamika
